Workbook

Sheet OpexCapex
C1: 202504 | D1: =IF(RIGHT(C1,1)<"4",C1+1,_xlfn.CONCAT(LEFT(C1,4)+1,"01")) -> 202601 | E1: =IF(RIGHT(D1,1)<"4",D1+1,_xlfn.CONCAT(LEFT(D1,4)+1,"01")) -> 202602 | F1: =IF(RIGHT(E1,1)<"4",E1+1,_xlfn.CONCAT(LEFT(E1,4)+1,"01")) -> 202603 | G1: =IF(RIGHT(F1,1)<"4",F1+1,_xlfn.CONCAT(LEFT(F1,4)+1,"01")) -> 202604 | H1: =IF(RIGHT(G1,1)<"4",G1+1,_xlfn.CONCAT(LEFT(G1,4)+1,"01")) -> 202701 | I1: =IF(RIGHT(H1,1)<"4",H1+1,_xlfn.CONCAT(LEFT(H1,4)+1,"01")) -> 202702 | J1: =IF(RIGHT(I1,1)<"4",I1+1,_xlfn.CONCAT(LEFT(I1,4)+1,"01")) -> 202703 | K1: =IF(RIGHT(J1,1)<"4",J1+1,_xlfn.CONCAT(LEFT(J1,4)+1,"01")) -> 202704 | ... AB1: =IF(RIGHT(AA1,1)<"4",AA1+1,_xlfn.CONCAT(LEFT(AA1,4)+1,"01")) -> 203201
B2: Stage | C2: Pre-Seed Round | E2: Seed-Round | K2: Series A | S2: Series B
B3: Cost Item/# of Units | C3: =_xlfn.CONCAT("Q",RIGHT(C1,1), " '",RIGHT(LEFT(C1,4),2)) -> Q4 '25 | D3: =_xlfn.CONCAT("Q",RIGHT(D1,1), " '",RIGHT(LEFT(D1,4),2)) -> Q1 '26 | E3: =_xlfn.CONCAT("Q",RIGHT(E1,1), " '",RIGHT(LEFT(E1,4),2)) -> Q2 '26 | F3: =_xlfn.CONCAT("Q",RIGHT(F1,1), " '",RIGHT(LEFT(F1,4),2)) -> Q3 '26 | G3: =_xlfn.CONCAT("Q",RIGHT(G1,1), " '",RIGHT(LEFT(G1,4),2)) -> Q4 '26 | H3: =_xlfn.CONCAT("Q",RIGHT(H1,1), " '",RIGHT(LEFT(H1,4),2)) -> Q1 '27 | I3: =_xlfn.CONCAT("Q",RIGHT(I1,1), " '",RIGHT(LEFT(I1,4),2)) -> Q2 '27 | J3: =_xlfn.CONCAT("Q",RIGHT(J1,1), " '",RIGHT(LEFT(J1,4),2)) -> Q3 '27 | ... AB3: =_xlfn.CONCAT("Q",RIGHT(AB1,1), " '",RIGHT(LEFT(AB1,4),2)) -> Q1 '32
B4: Staff
B5: UK Market
B6: Software Engineers | C6: 2 | D6: 2 | E6: 2 | F6: 2 | G6: 2 | H6: 2 | I6: 2 | J6: 2 | K6: 4 | L6: 4 | M6: 4 | N6: 4 | O6: 4 | P6: 4 | Q6: 4 | R6: 4 | S6: 8 | T6: 8 | U6: 8 | V6: 8 | W6: 8 | X6: 8 | Y6: 8 | Z6: 8 | AA6: 8 | AB6: 8
B7: Data Scientists | C7: 2 | D7: 2 | E7: 3 | F7: 3 | G7: 3 | H7: 3 | I7: 3 | J7: 3 | K7: 4 | L7: 4 | M7: 4 | N7: 4 | O7: 4 | P7: 4 | Q7: 4 | R7: 4 | S7: 4 | T7: 4 | U7: 4 | V7: 4 | W7: 4 | X7: 4 | Y7: 4 | Z7: 4 | AA7: 4 | AB7: 4
B8: HR & Legal | C8: 0 | D8: 0 | E8: 2 | F8: 2 | G8: 2 | H8: 2 | I8: 2 | J8: 2 | K8: 2 | L8: 2 | M8: 2 | N8: 2 | O8: 2 | P8: 2 | Q8: 2 | R8: 2 | S8: 2 | T8: 2 | U8: 2 | V8: 2 | W8: 2 | X8: 2 | Y8: 2 | Z8: 2 | AA8: 2 | AB8: 2
B9: Graphic Designers | C9: 0 | D9: 0 | E9: 1 | F9: 1 | G9: 1 | H9: 1 | I9: 1 | J9: 1 | K9: 1 | L9: 1 | M9: 1 | N9: 1 | O9: 1 | P9: 1 | Q9: 1 | R9: 1 | S9: 2 | T9: 2 | U9: 2 | V9: 2 | W9: 2 | X9: 2 | Y9: 2 | Z9: 2 | AA9: 2 | AB9: 2
B10: Business Development | C10: 0 | D10: 2 | E10: 4 | F10: 4 | G10: 4 | H10: 4 | I10: 4 | J10: 4 | K10: 6 | L10: 6 | M10: 6 | N10: 6 | O10: 6 | P10: 6 | Q10: 6 | R10: 6 | S10: 10 | T10: 10 | U10: 10 | V10: 10 | W10: 10 | X10: 10 | Y10: 10 | Z10: 10 | AA10: 10 | AB10: 10
B11: Marketing Manager | C11: 0 | D11: 1 | E11: 1 | F11: 1 | G11: 1 | H11: 1 | I11: 1 | J11: 1 | K11: 2 | L11: 2 | M11: 2 | N11: 2 | O11: 2 | P11: 2 | Q11: 2 | R11: 2 | S11: 4 | T11: 4 | U11: 4 | V11: 4 | W11: 4 | X11: 4 | Y11: 4 | Z11: 4 | AA11: 4 | AB11: 4
B12: Business Analyst | C12: 0 | D12: 0 | E12: 0 | F12: 0 | G12: 1 | H12: 1 | I12: 1 | J12: 1 | K12: 1 | L12: 1 | M12: 1 | N12: 1 | O12: 1 | P12: 1 | Q12: 1 | R12: 1 | S12: 2 | T12: 2 | U12: 2 | V12: 2 | W12: 2 | X12: 2 | Y12: 2 | Z12: 2 | AA12: 2 | AB12: 2
B13: US Market*
B14: Software Engineers | C14: 0 | D14: 0 | E14: 0 | F14: 0 | G14: 0 | H14: 0 | I14: 0 | J14: 0 | K14: 0 | L14: 0 | M14: 0 | N14: 0 | O14: 0 | P14: 0 | Q14: 0 | R14: 0 | S14: 8 | T14: 8 | U14: 8 | V14: 8 | W14: 8 | X14: 8 | Y14: 8 | Z14: 8 | AA14: 8 | AB14: 8
B15: Data Scientists | C15: 0 | D15: 0 | E15: 0 | F15: 0 | G15: 0 | H15: 0 | I15: 0 | J15: 0 | K15: 0 | L15: 0 | M15: 0 | N15: 0 | O15: 0 | P15: 0 | Q15: 0 | R15: 0 | S15: 4 | T15: 4 | U15: 4 | V15: 4 | W15: 4 | X15: 4 | Y15: 4 | Z15: 4 | AA15: 4 | AB15: 4
B16: HR & Legal | C16: 0 | D16: 0 | E16: 0 | F16: 0 | G16: 0 | H16: 0 | I16: 0 | J16: 0 | K16: 0 | L16: 0 | M16: 0 | N16: 0 | O16: 0 | P16: 0 | Q16: 0 | R16: 0 | S16: 2 | T16: 2 | U16: 2 | V16: 2 | W16: 2 | X16: 2 | Y16: 2 | Z16: 2 | AA16: 2 | AB16: 2
B17: Graphic Designers | C17: 0 | D17: 0 | E17: 0 | F17: 0 | G17: 0 | H17: 0 | I17: 0 | J17: 0 | K17: 0 | L17: 0 | M17: 0 | N17: 0 | O17: 0 | P17: 0 | Q17: 0 | R17: 0 | S17: 2 | T17: 2 | U17: 2 | V17: 2 | W17: 2 | X17: 2 | Y17: 2 | Z17: 2 | AA17: 2 | AB17: 2
B18: Business Development | C18: 0 | D18: 0 | E18: 0 | F18: 0 | G18: 0 | H18: 0 | I18: 0 | J18: 0 | K18: 0 | L18: 0 | M18: 0 | N18: 0 | O18: 0 | P18: 0 | Q18: 0 | R18: 0 | S18: 10 | T18: 10 | U18: 10 | V18: 10 | W18: 10 | X18: 10 | Y18: 10 | Z18: 10 | AA18: 10 | AB18: 10
B19: Marketing Manager | C19: 0 | D19: 0 | E19: 0 | F19: 0 | G19: 0 | H19: 0 | I19: 0 | J19: 0 | K19: 0 | L19: 0 | M19: 0 | N19: 0 | O19: 0 | P19: 0 | Q19: 0 | R19: 0 | S19: 4 | T19: 4 | U19: 4 | V19: 4 | W19: 4 | X19: 4 | Y19: 4 | Z19: 4 | AA19: 4 | AB19: 4
B20: Business Analyst | C20: 0 | D20: 0 | E20: 0 | F20: 0 | G20: 0 | H20: 0 | I20: 0 | J20: 0 | K20: 0 | L20: 0 | M20: 0 | N20: 0 | O20: 0 | P20: 0 | Q20: 0 | R20: 0 | S20: 2 | T20: 2 | U20: 2 | V20: 2 | W20: 2 | X20: 2 | Y20: 2 | Z20: 2 | AA20: 2 | AB20: 2
B21: Technology Cost
B22: UK Market
B23: Cloud Services | C23: 1 | D23: 1 | E23: 1 | F23: 1 | G23: 1 | H23: 1 | I23: 1 | J23: 1 | K23: 1 | L23: 1 | M23: 1 | N23: 1 | O23: 1 | P23: 1 | Q23: 1 | R23: 1 | S23: 1 | T23: 1 | U23: 1 | V23: 1 | W23: 1 | X23: 1 | Y23: 1 | Z23: 1 | AA23: 1 | AB23: 1
B24: US Market
B25: Cloud Services | C25: 0 | D25: 0 | E25: 0 | F25: 0 | G25: 0 | H25: 0 | I25: 0 | J25: 0 | K25: 0 | L25: 0 | M25: 0 | N25: 0 | O25: 0 | P25: 0 | Q25: 0 | R25: 0 | S25: 1 | T25: 1 | U25: 1 | V25: 1 | W25: 1 | X25: 1 | Y25: 1 | Z25: 1 | AA25: 1 | AB25: 1
B26: Physical Office
B27: UK Market
B28: Rent | C28: 1 | D28: 1 | E28: 1 | F28: 1 | G28: 1 | H28: 1 | I28: 1 | J28: 1 | K28: 1 | L28: 1 | M28: 1 | N28: 1 | O28: 1 | P28: 1 | Q28: 1 | R28: 1 | S28: 1 | T28: 1 | U28: 1 | V28: 1 | W28: 1 | X28: 1 | Y28: 1 | Z28: 1 | AA28: 1 | AB28: 1
B29: US Market
B30: Rent | C30: 0 | D30: 0 | E30: 0 | F30: 0 | G30: 0 | H30: 0 | I30: 0 | J30: 0 | K30: 0 | L30: 0 | M30: 0 | N30: 0 | O30: 0 | P30: 0 | Q30: 0 | R30: 0 | S30: 1 | T30: 1 | U30: 1 | V30: 1 | W30: 1 | X30: 1 | Y30: 1 | Z30: 1 | AA30: 1 | AB30: 1
B31: * Assuming same size as UK Market operating at efficiency.
B32: ** Assuming 10% 1 Month Retention Rate & 5% 2 Months Retention & 3% 3 Months Retention

Sheet Quarterly
E1: 202504 | F1: =IF(RIGHT(E1,1)<"4",E1+1,_xlfn.CONCAT(LEFT(E1,4)+1,"01")) -> 202601 | G1: =IF(RIGHT(F1,1)<"4",F1+1,_xlfn.CONCAT(LEFT(F1,4)+1,"01")) -> 202602 | H1: =IF(RIGHT(G1,1)<"4",G1+1,_xlfn.CONCAT(LEFT(G1,4)+1,"01")) -> 202603 | I1: =IF(RIGHT(H1,1)<"4",H1+1,_xlfn.CONCAT(LEFT(H1,4)+1,"01")) -> 202604 | J1: =IF(RIGHT(I1,1)<"4",I1+1,_xlfn.CONCAT(LEFT(I1,4)+1,"01")) -> 202701 | K1: =IF(RIGHT(J1,1)<"4",J1+1,_xlfn.CONCAT(LEFT(J1,4)+1,"01")) -> 202702 | L1: =IF(RIGHT(K1,1)<"4",K1+1,_xlfn.CONCAT(LEFT(K1,4)+1,"01")) -> 202703 | M1: =IF(RIGHT(L1,1)<"4",L1+1,_xlfn.CONCAT(LEFT(L1,4)+1,"01")) -> 202704 | ... AD1: =IF(RIGHT(AC1,1)<"4",AC1+1,_xlfn.CONCAT(LEFT(AC1,4)+1,"01")) -> 203201
C2: Stage | E2: Pre-Seed Round | G2: Seed-Round | M2: Series A | U2: Series B
C3: Cost Item | D3: Cost per Unit | E3: =_xlfn.CONCAT("Q",RIGHT(E1,1), " '",RIGHT(LEFT(E1,4),2)) -> Q4 '25 | F3: =_xlfn.CONCAT("Q",RIGHT(F1,1), " '",RIGHT(LEFT(F1,4),2)) -> Q1 '26 | G3: =_xlfn.CONCAT("Q",RIGHT(G1,1), " '",RIGHT(LEFT(G1,4),2)) -> Q2 '26 | H3: =_xlfn.CONCAT("Q",RIGHT(H1,1), " '",RIGHT(LEFT(H1,4),2)) -> Q3 '26 | I3: =_xlfn.CONCAT("Q",RIGHT(I1,1), " '",RIGHT(LEFT(I1,4),2)) -> Q4 '26 | J3: =_xlfn.CONCAT("Q",RIGHT(J1,1), " '",RIGHT(LEFT(J1,4),2)) -> Q1 '27 | K3: =_xlfn.CONCAT("Q",RIGHT(K1,1), " '",RIGHT(LEFT(K1,4),2)) -> Q2 '27 | L3: =_xlfn.CONCAT("Q",RIGHT(L1,1), " '",RIGHT(LEFT(L1,4),2)) -> Q3 '27 | ... AD3: =_xlfn.CONCAT("Q",RIGHT(AD1,1), " '",RIGHT(LEFT(AD1,4),2)) -> Q1 '32
C4: Total (in £ '000) | E4: =E5+E22+E27 -> 40000 | F4: =F5+F22+F27 -> 47500 | G4: =G5+G22+G27 -> 66500 | H4: =H5+H22+H27 -> 66500 | I4: =I5+I22+I27 -> 70000 | J4: =J5+J22+J27 -> 70000 | K4: =K5+K22+K27 -> 70000 | L4: =L5+L22+L27 -> 70000 | ... AD4: =AD5+AD22+AD27 -> 268000
C5: Staff (in £ '000) | E5: =E6+E14 -> 20000 | F5: =F6+F14 -> 27500 | G5: =G6+G14 -> 46500 | H5: =H6+H14 -> 46500 | I5: =I6+I14 -> 50000 | J5: =J6+J14 -> 50000 | K5: =K6+K14 -> 50000 | L5: =L6+L14 -> 50000 | ... AD5: =AD6+AD14 -> 228000
C6: UK Market | E6: =SUM(E7:E13) -> 20000 | F6: =SUM(F7:F13) -> 27500 | G6: =SUM(G7:G13) -> 46500 | H6: =SUM(H7:H13) -> 46500 | I6: =SUM(I7:I13) -> 50000 | J6: =SUM(J7:J13) -> 50000 | K6: =SUM(K7:K13) -> 50000 | L6: =SUM(L7:L13) -> 50000 | ... AD6: =SUM(AD7:AD13) -> 114000
C7: Software Engineers | D7: =60000/12 -> 5000 | E7: =OpexCapex!C6*$D7 -> 10000 | F7: =OpexCapex!D6*$D7 -> 10000 | G7: =OpexCapex!E6*$D7 -> 10000 | H7: =OpexCapex!F6*$D7 -> 10000 | I7: =OpexCapex!G6*$D7 -> 10000 | J7: =OpexCapex!H6*$D7 -> 10000 | K7: =OpexCapex!I6*$D7 -> 10000 | L7: =OpexCapex!J6*$D7 -> 10000 | ... AD7: =OpexCapex!AB6*$D7 -> 40000
C8: Data Scientists | D8: 5000 | E8: =OpexCapex!C7*$D8 -> 10000 | F8: =OpexCapex!D7*$D8 -> 10000 | G8: =OpexCapex!E7*$D8 -> 15000 | H8: =OpexCapex!F7*$D8 -> 15000 | I8: =OpexCapex!G7*$D8 -> 15000 | J8: =OpexCapex!H7*$D8 -> 15000 | K8: =OpexCapex!I7*$D8 -> 15000 | L8: =OpexCapex!J7*$D8 -> 15000 | ... AD8: =OpexCapex!AB7*$D8 -> 20000
C9: HR & Legal | D9: 3000 | E9: =OpexCapex!C8*$D9 -> 0 | F9: =OpexCapex!D8*$D9 -> 0 | G9: =OpexCapex!E8*$D9 -> 6000 | H9: =OpexCapex!F8*$D9 -> 6000 | I9: =OpexCapex!G8*$D9 -> 6000 | J9: =OpexCapex!H8*$D9 -> 6000 | K9: =OpexCapex!I8*$D9 -> 6000 | L9: =OpexCapex!J8*$D9 -> 6000 | ... AD9: =OpexCapex!AB8*$D9 -> 6000
C10: Graphic Designers | D10: 3000 | E10: =OpexCapex!C9*$D10 -> 0 | F10: =OpexCapex!D9*$D10 -> 0 | G10: =OpexCapex!E9*$D10 -> 3000 | H10: =OpexCapex!F9*$D10 -> 3000 | I10: =OpexCapex!G9*$D10 -> 3000 | J10: =OpexCapex!H9*$D10 -> 3000 | K10: =OpexCapex!I9*$D10 -> 3000 | L10: =OpexCapex!J9*$D10 -> 3000 | ... AD10: =OpexCapex!AB9*$D10 -> 6000
C11: Business Development | D11: 2500 | E11: =OpexCapex!C10*$D11 -> 0 | F11: =OpexCapex!D10*$D11 -> 5000 | G11: =OpexCapex!E10*$D11 -> 10000 | H11: =OpexCapex!F10*$D11 -> 10000 | I11: =OpexCapex!G10*$D11 -> 10000 | J11: =OpexCapex!H10*$D11 -> 10000 | K11: =OpexCapex!I10*$D11 -> 10000 | L11: =OpexCapex!J10*$D11 -> 10000 | ... AD11: =OpexCapex!AB10*$D11 -> 25000
C12: Marketing Manager | D12: 2500 | E12: =OpexCapex!C11*$D12 -> 0 | F12: =OpexCapex!D11*$D12 -> 2500 | G12: =OpexCapex!E11*$D12 -> 2500 | H12: =OpexCapex!F11*$D12 -> 2500 | I12: =OpexCapex!G11*$D12 -> 2500 | J12: =OpexCapex!H11*$D12 -> 2500 | K12: =OpexCapex!I11*$D12 -> 2500 | L12: =OpexCapex!J11*$D12 -> 2500 | ... AD12: =OpexCapex!AB11*$D12 -> 10000
C13: Business Analyst | D13: 3500 | E13: =OpexCapex!C12*$D13 -> 0 | F13: =OpexCapex!D12*$D13 -> 0 | G13: =OpexCapex!E12*$D13 -> 0 | H13: =OpexCapex!F12*$D13 -> 0 | I13: =OpexCapex!G12*$D13 -> 3500 | J13: =OpexCapex!H12*$D13 -> 3500 | K13: =OpexCapex!I12*$D13 -> 3500 | L13: =OpexCapex!J12*$D13 -> 3500 | ... AD13: =OpexCapex!AB12*$D13 -> 7000
C14: US Market | E14: =SUM(E15:E21) -> 0 | F14: =SUM(F15:F21) -> 0 | G14: =SUM(G15:G21) -> 0 | H14: =SUM(H15:H21) -> 0 | I14: =SUM(I15:I21) -> 0 | J14: =SUM(J15:J21) -> 0 | K14: =SUM(K15:K21) -> 0 | L14: =SUM(L15:L21) -> 0 | ... AD14: =SUM(AD15:AD21) -> 114000
C15: Software Engineers | D15: =60000/12 -> 5000 | E15: =$D15*OpexCapex!C14 -> 0 | F15: =$D15*OpexCapex!D14 -> 0 | G15: =$D15*OpexCapex!E14 -> 0 | H15: =$D15*OpexCapex!F14 -> 0 | I15: =$D15*OpexCapex!G14 -> 0 | J15: =$D15*OpexCapex!H14 -> 0 | K15: =$D15*OpexCapex!I14 -> 0 | L15: =$D15*OpexCapex!J14 -> 0 | ... AD15: =$D15*OpexCapex!AB14 -> 40000
C16: Data Scientists | D16: 5000 | E16: =$D16*OpexCapex!C15 -> 0 | F16: =$D16*OpexCapex!D15 -> 0 | G16: =$D16*OpexCapex!E15 -> 0 | H16: =$D16*OpexCapex!F15 -> 0 | I16: =$D16*OpexCapex!G15 -> 0 | J16: =$D16*OpexCapex!H15 -> 0 | K16: =$D16*OpexCapex!I15 -> 0 | L16: =$D16*OpexCapex!J15 -> 0 | ... AD16: =$D16*OpexCapex!AB15 -> 20000
C17: HR & Legal | D17: 3000 | E17: =$D17*OpexCapex!C16 -> 0 | F17: =$D17*OpexCapex!D16 -> 0 | G17: =$D17*OpexCapex!E16 -> 0 | H17: =$D17*OpexCapex!F16 -> 0 | I17: =$D17*OpexCapex!G16 -> 0 | J17: =$D17*OpexCapex!H16 -> 0 | K17: =$D17*OpexCapex!I16 -> 0 | L17: =$D17*OpexCapex!J16 -> 0 | ... AD17: =$D17*OpexCapex!AB16 -> 6000
C18: Graphic Designers | D18: 3000 | E18: =$D18*OpexCapex!C17 -> 0 | F18: =$D18*OpexCapex!D17 -> 0 | G18: =$D18*OpexCapex!E17 -> 0 | H18: =$D18*OpexCapex!F17 -> 0 | I18: =$D18*OpexCapex!G17 -> 0 | J18: =$D18*OpexCapex!H17 -> 0 | K18: =$D18*OpexCapex!I17 -> 0 | L18: =$D18*OpexCapex!J17 -> 0 | ... AD18: =$D18*OpexCapex!AB17 -> 6000
C19: Business Development | D19: 2500 | E19: =$D19*OpexCapex!C18 -> 0 | F19: =$D19*OpexCapex!D18 -> 0 | G19: =$D19*OpexCapex!E18 -> 0 | H19: =$D19*OpexCapex!F18 -> 0 | I19: =$D19*OpexCapex!G18 -> 0 | J19: =$D19*OpexCapex!H18 -> 0 | K19: =$D19*OpexCapex!I18 -> 0 | L19: =$D19*OpexCapex!J18 -> 0 | ... AD19: =$D19*OpexCapex!AB18 -> 25000
C20: Marketing Manager | D20: 2500 | E20: =$D20*OpexCapex!C19 -> 0 | F20: =$D20*OpexCapex!D19 -> 0 | G20: =$D20*OpexCapex!E19 -> 0 | H20: =$D20*OpexCapex!F19 -> 0 | I20: =$D20*OpexCapex!G19 -> 0 | J20: =$D20*OpexCapex!H19 -> 0 | K20: =$D20*OpexCapex!I19 -> 0 | L20: =$D20*OpexCapex!J19 -> 0 | ... AD20: =$D20*OpexCapex!AB19 -> 10000
C21: Business Analyst | D21: 3500 | E21: =$D21*OpexCapex!C20 -> 0 | F21: =$D21*OpexCapex!D20 -> 0 | G21: =$D21*OpexCapex!E20 -> 0 | H21: =$D21*OpexCapex!F20 -> 0 | I21: =$D21*OpexCapex!G20 -> 0 | J21: =$D21*OpexCapex!H20 -> 0 | K21: =$D21*OpexCapex!I20 -> 0 | L21: =$D21*OpexCapex!J20 -> 0 | ... AD21: =$D21*OpexCapex!AB20 -> 7000
C22: Technology Cost (in £ '000) | E22: =E23+E25 -> 10000 | F22: =F23+F25 -> 10000 | G22: =G23+G25 -> 10000 | H22: =H23+H25 -> 10000 | I22: =I23+I25 -> 10000 | J22: =J23+J25 -> 10000 | K22: =K23+K25 -> 10000 | L22: =L23+L25 -> 10000 | ... AD22: =AD23+AD25 -> 20000
C23: UK Market | E23: =SUM(E24:E24) -> 10000 | F23: =SUM(F24:F24) -> 10000 | G23: =SUM(G24:G24) -> 10000 | H23: =SUM(H24:H24) -> 10000 | I23: =SUM(I24:I24) -> 10000 | J23: =SUM(J24:J24) -> 10000 | K23: =SUM(K24:K24) -> 10000 | L23: =SUM(L24:L24) -> 10000 | ... AD23: =SUM(AD24:AD24) -> 10000
C24: Cloud Services | D24: 10000 | E24: =$D24*OpexCapex!C23 -> 10000 | F24: =$D24*OpexCapex!D23 -> 10000 | G24: =$D24*OpexCapex!E23 -> 10000 | H24: =$D24*OpexCapex!F23 -> 10000 | I24: =$D24*OpexCapex!G23 -> 10000 | J24: =$D24*OpexCapex!H23 -> 10000 | K24: =$D24*OpexCapex!I23 -> 10000 | L24: =$D24*OpexCapex!J23 -> 10000 | ... AD24: =$D24*OpexCapex!AB23 -> 10000
C25: US Market | E25: =SUM(E26:E26) -> 0 | F25: =SUM(F26:F26) -> 0 | G25: =SUM(G26:G26) -> 0 | H25: =SUM(H26:H26) -> 0 | I25: =SUM(I26:I26) -> 0 | J25: =SUM(J26:J26) -> 0 | K25: =SUM(K26:K26) -> 0 | L25: =SUM(L26:L26) -> 0 | ... AD25: =SUM(AD26:AD26) -> 10000
C26: Cloud Services | D26: 10000 | E26: =$D26*OpexCapex!C25 -> 0 | F26: =$D26*OpexCapex!D25 -> 0 | G26: =$D26*OpexCapex!E25 -> 0 | H26: =$D26*OpexCapex!F25 -> 0 | I26: =$D26*OpexCapex!G25 -> 0 | J26: =$D26*OpexCapex!H25 -> 0 | K26: =$D26*OpexCapex!I25 -> 0 | L26: =$D26*OpexCapex!J25 -> 0 | ... AD26: =$D26*OpexCapex!AB25 -> 10000
C27: Physical Office | E27: =SUM(E28,E30) -> 10000 | F27: =SUM(F28,F30) -> 10000 | G27: =SUM(G28,G30) -> 10000 | H27: =SUM(H28,H30) -> 10000 | I27: =SUM(I28,I30) -> 10000 | J27: =SUM(J28,J30) -> 10000 | K27: =SUM(K28,K30) -> 10000 | L27: =SUM(L28,L30) -> 10000 | ... AD27: =SUM(AD28,AD30) -> 20000
C28: UK Market | E28: =SUM(E29:E29) -> 10000 | F28: =SUM(F29:F29) -> 10000 | G28: =SUM(G29:G29) -> 10000 | H28: =SUM(H29:H29) -> 10000 | I28: =SUM(I29:I29) -> 10000 | J28: =SUM(J29:J29) -> 10000 | K28: =SUM(K29:K29) -> 10000 | L28: =SUM(L29:L29) -> 10000 | ... AD28: =SUM(AD29:AD29) -> 10000
C29: Rent | D29: 10000 | E29: =$D29*OpexCapex!C28 -> 10000 | F29: =$D29*OpexCapex!D28 -> 10000 | G29: =$D29*OpexCapex!E28 -> 10000 | H29: =$D29*OpexCapex!F28 -> 10000 | I29: =$D29*OpexCapex!G28 -> 10000 | J29: =$D29*OpexCapex!H28 -> 10000 | K29: =$D29*OpexCapex!I28 -> 10000 | L29: =$D29*OpexCapex!J28 -> 10000 | ... AD29: =$D29*OpexCapex!AB28 -> 10000
C30: US Market | E30: =SUM(E31:E31) -> 0 | F30: =SUM(F31:F31) -> 0 | G30: =SUM(G31:G31) -> 0 | H30: =SUM(H31:H31) -> 0 | I30: =SUM(I31:I31) -> 0 | J30: =SUM(J31:J31) -> 0 | K30: =SUM(K31:K31) -> 0 | L30: =SUM(L31:L31) -> 0 | ... AD30: =SUM(AD31:AD31) -> 10000
C31: Rent | D31: 10000 | E31: =$D31*OpexCapex!C30 -> 0 | F31: =$D31*OpexCapex!D30 -> 0 | G31: =$D31*OpexCapex!E30 -> 0 | H31: =$D31*OpexCapex!F30 -> 0 | I31: =$D31*OpexCapex!G30 -> 0 | J31: =$D31*OpexCapex!H30 -> 0 | K31: =$D31*OpexCapex!I30 -> 0 | L31: =$D31*OpexCapex!J30 -> 0 | ... AD31: =$D31*OpexCapex!AB30 -> 10000

Sheet Annual
C2: Annual Costs | D2: (in £ '000) | K2: (YoY %)
C3: Cost Item | D3: 2026 | E3: 2027 | F3: 2028 | G3: 2029 | H3: 3030 | I3: 3031 | J3: 3032 | K3: 2027 | L3: 2028 | M3: 2029 | N3: 3030 | O3: 3031 | P3: 3032
C4: Total (in £ '000) | D4: =SUM(Quarterly!E4:I4) -> 290500 | E4: =SUM(Quarterly!J4:M4) -> 302500 | F4: =SUM(Quarterly!N4:Q4) -> 370000 | G4: =SUM(Quarterly!R4:U4) -> 545500 | H4: =SUM(Quarterly!V4:Y4) -> 1072000 | I4: =SUM(Quarterly!Z4:AC4) -> 1072000 | J4: =Quarterly!AD4*4 -> 1072000 | K4: =IFERROR(E4/D4-1,0) -> 0.04130809 | L4: =IFERROR(F4/E4-1,0) -> 0.2231405 | M4: =IFERROR(G4/F4-1,0) -> 0.47432432 | N4: =IFERROR(H4/G4-1,0) -> 0.96516957 | O4: =IFERROR(I4/H4-1,0) -> 0 | P4: =IFERROR(J4/I4-1,0) -> 0
C5: Staff (in £ '000) | D5: =SUM(Quarterly!E5:I5) -> 190500 | E5: =SUM(Quarterly!J5:M5) -> 222500 | F5: =SUM(Quarterly!N5:Q5) -> 290000 | G5: =SUM(Quarterly!R5:U5) -> 445500 | H5: =SUM(Quarterly!V5:Y5) -> 912000 | I5: =SUM(Quarterly!Z5:AC5) -> 912000 | J5: =Quarterly!AD5*4 -> 912000 | K5: =IFERROR(E5/D5-1,0) -> 0.167979 | L5: =IFERROR(F5/E5-1,0) -> 0.30337079 | M5: =IFERROR(G5/F5-1,0) -> 0.5362069 | N5: =IFERROR(H5/G5-1,0) -> 1.047138 | O5: =IFERROR(I5/H5-1,0) -> 0 | P5: =IFERROR(J5/I5-1,0) -> 0
C6: UK Market | D6: =SUM(Quarterly!E6:I6) -> 190500 | E6: =SUM(Quarterly!J6:M6) -> 222500 | F6: =SUM(Quarterly!N6:Q6) -> 290000 | G6: =SUM(Quarterly!R6:U6) -> 331500 | H6: =SUM(Quarterly!V6:Y6) -> 456000 | I6: =SUM(Quarterly!Z6:AC6) -> 456000 | J6: =Quarterly!AD6*4 -> 456000 | K6: =IFERROR(E6/D6-1,0) -> 0.167979 | L6: =IFERROR(F6/E6-1,0) -> 0.30337079 | M6: =IFERROR(G6/F6-1,0) -> 0.14310345 | N6: =IFERROR(H6/G6-1,0) -> 0.37556561 | O6: =IFERROR(I6/H6-1,0) -> 0 | P6: =IFERROR(J6/I6-1,0) -> 0
C7: Software Engineers | D7: =SUM(Quarterly!E7:I7) -> 50000 | E7: =SUM(Quarterly!J7:M7) -> 50000 | F7: =SUM(Quarterly!N7:Q7) -> 80000 | G7: =SUM(Quarterly!R7:U7) -> 100000 | H7: =SUM(Quarterly!V7:Y7) -> 160000 | I7: =SUM(Quarterly!Z7:AC7) -> 160000 | J7: =Quarterly!AD7*4 -> 160000 | K7: =IFERROR(E7/D7-1,0) -> 0 | L7: =IFERROR(F7/E7-1,0) -> 0.6 | M7: =IFERROR(G7/F7-1,0) -> 0.25 | N7: =IFERROR(H7/G7-1,0) -> 0.6 | O7: =IFERROR(I7/H7-1,0) -> 0 | P7: =IFERROR(J7/I7-1,0) -> 0
C8: Data Scientists | D8: =SUM(Quarterly!E8:I8) -> 65000 | E8: =SUM(Quarterly!J8:M8) -> 65000 | F8: =SUM(Quarterly!N8:Q8) -> 80000 | G8: =SUM(Quarterly!R8:U8) -> 80000 | H8: =SUM(Quarterly!V8:Y8) -> 80000 | I8: =SUM(Quarterly!Z8:AC8) -> 80000 | J8: =Quarterly!AD8*4 -> 80000 | K8: =IFERROR(E8/D8-1,0) -> 0 | L8: =IFERROR(F8/E8-1,0) -> 0.23076923 | M8: =IFERROR(G8/F8-1,0) -> 0 | N8: =IFERROR(H8/G8-1,0) -> 0 | O8: =IFERROR(I8/H8-1,0) -> 0 | P8: =IFERROR(J8/I8-1,0) -> 0
C9: HR & Legal | D9: =SUM(Quarterly!E9:I9) -> 18000 | E9: =SUM(Quarterly!J9:M9) -> 24000 | F9: =SUM(Quarterly!N9:Q9) -> 24000 | G9: =SUM(Quarterly!R9:U9) -> 24000 | H9: =SUM(Quarterly!V9:Y9) -> 24000 | I9: =SUM(Quarterly!Z9:AC9) -> 24000 | J9: =Quarterly!AD9*4 -> 24000 | K9: =IFERROR(E9/D9-1,0) -> 0.33333333 | L9: =IFERROR(F9/E9-1,0) -> 0 | M9: =IFERROR(G9/F9-1,0) -> 0 | N9: =IFERROR(H9/G9-1,0) -> 0 | O9: =IFERROR(I9/H9-1,0) -> 0 | P9: =IFERROR(J9/I9-1,0) -> 0
C10: Graphic Designers | D10: =SUM(Quarterly!E10:I10) -> 9000 | E10: =SUM(Quarterly!J10:M10) -> 12000 | F10: =SUM(Quarterly!N10:Q10) -> 12000 | G10: =SUM(Quarterly!R10:U10) -> 15000 | H10: =SUM(Quarterly!V10:Y10) -> 24000 | I10: =SUM(Quarterly!Z10:AC10) -> 24000 | J10: =Quarterly!AD10*4 -> 24000 | K10: =IFERROR(E10/D10-1,0) -> 0.33333333 | L10: =IFERROR(F10/E10-1,0) -> 0 | M10: =IFERROR(G10/F10-1,0) -> 0.25 | N10: =IFERROR(H10/G10-1,0) -> 0.6 | O10: =IFERROR(I10/H10-1,0) -> 0 | P10: =IFERROR(J10/I10-1,0) -> 0
C11: Business Development | D11: =SUM(Quarterly!E11:I11) -> 35000 | E11: =SUM(Quarterly!J11:M11) -> 45000 | F11: =SUM(Quarterly!N11:Q11) -> 60000 | G11: =SUM(Quarterly!R11:U11) -> 70000 | H11: =SUM(Quarterly!V11:Y11) -> 100000 | I11: =SUM(Quarterly!Z11:AC11) -> 100000 | J11: =Quarterly!AD11*4 -> 100000 | K11: =IFERROR(E11/D11-1,0) -> 0.28571429 | L11: =IFERROR(F11/E11-1,0) -> 0.33333333 | M11: =IFERROR(G11/F11-1,0) -> 0.16666667 | N11: =IFERROR(H11/G11-1,0) -> 0.42857143 | O11: =IFERROR(I11/H11-1,0) -> 0 | P11: =IFERROR(J11/I11-1,0) -> 0
C12: Marketing Manager | D12: =SUM(Quarterly!E12:I12) -> 10000 | E12: =SUM(Quarterly!J12:M12) -> 12500 | F12: =SUM(Quarterly!N12:Q12) -> 20000 | G12: =SUM(Quarterly!R12:U12) -> 25000 | H12: =SUM(Quarterly!V12:Y12) -> 40000 | I12: =SUM(Quarterly!Z12:AC12) -> 40000 | J12: =Quarterly!AD12*4 -> 40000 | K12: =IFERROR(E12/D12-1,0) -> 0.25 | L12: =IFERROR(F12/E12-1,0) -> 0.6 | M12: =IFERROR(G12/F12-1,0) -> 0.25 | N12: =IFERROR(H12/G12-1,0) -> 0.6 | O12: =IFERROR(I12/H12-1,0) -> 0 | P12: =IFERROR(J12/I12-1,0) -> 0
C13: Business Analyst | D13: =SUM(Quarterly!E13:I13) -> 3500 | E13: =SUM(Quarterly!J13:M13) -> 14000 | F13: =SUM(Quarterly!N13:Q13) -> 14000 | G13: =SUM(Quarterly!R13:U13) -> 17500 | H13: =SUM(Quarterly!V13:Y13) -> 28000 | I13: =SUM(Quarterly!Z13:AC13) -> 28000 | J13: =Quarterly!AD13*4 -> 28000 | K13: =IFERROR(E13/D13-1,0) -> 3 | L13: =IFERROR(F13/E13-1,0) -> 0 | M13: =IFERROR(G13/F13-1,0) -> 0.25 | N13: =IFERROR(H13/G13-1,0) -> 0.6 | O13: =IFERROR(I13/H13-1,0) -> 0 | P13: =IFERROR(J13/I13-1,0) -> 0
C14: US Market | D14: =SUM(Quarterly!E14:I14) -> 0 | E14: =SUM(Quarterly!J14:M14) -> 0 | F14: =SUM(Quarterly!N14:Q14) -> 0 | G14: =SUM(Quarterly!R14:U14) -> 114000 | H14: =SUM(Quarterly!V14:Y14) -> 456000 | I14: =SUM(Quarterly!Z14:AC14) -> 456000 | J14: =Quarterly!AD14*4 -> 456000 | K14: =IFERROR(E14/D14-1,0) -> 0 | L14: =IFERROR(F14/E14-1,0) -> 0 | M14: =IFERROR(G14/F14-1,0) -> 0 | N14: =IFERROR(H14/G14-1,0) -> 3 | O14: =IFERROR(I14/H14-1,0) -> 0 | P14: =IFERROR(J14/I14-1,0) -> 0
C15: Software Engineers | D15: =SUM(Quarterly!E15:I15) -> 0 | E15: =SUM(Quarterly!J15:M15) -> 0 | F15: =SUM(Quarterly!N15:Q15) -> 0 | G15: =SUM(Quarterly!R15:U15) -> 40000 | H15: =SUM(Quarterly!V15:Y15) -> 160000 | I15: =SUM(Quarterly!Z15:AC15) -> 160000 | J15: =Quarterly!AD15*4 -> 160000 | K15: =IFERROR(E15/D15-1,0) -> 0 | L15: =IFERROR(F15/E15-1,0) -> 0 | M15: =IFERROR(G15/F15-1,0) -> 0 | N15: =IFERROR(H15/G15-1,0) -> 3 | O15: =IFERROR(I15/H15-1,0) -> 0 | P15: =IFERROR(J15/I15-1,0) -> 0
... C23: UK Market | D23: =SUM(Quarterly!E23:I23) -> 50000 | E23: =SUM(Quarterly!J23:M23) -> 40000 | F23: =SUM(Quarterly!N23:Q23) -> 40000 | G23: =SUM(Quarterly!R23:U23) -> 40000 | H23: =SUM(Quarterly!V23:Y23) -> 40000 | I23: =SUM(Quarterly!Z23:AC23) -> 40000 | J23: =Quarterly!AD23*4 -> 40000 | K23: =IFERROR(E23/D23-1,0) -> -0.2 | L23: =IFERROR(F23/E23-1,0) -> 0 | M23: =IFERROR(G23/F23-1,0) -> 0 | N23: =IFERROR(H23/G23-1,0) -> 0 | O23: =IFERROR(I23/H23-1,0) -> 0 | P23: =IFERROR(J23/I23-1,0) -> 0
C24: New Customer Acquistion (B2C) | D24: =SUM(Quarterly!#REF!) -> #REF! | E24: =SUM(Quarterly!#REF!) -> #REF! | F24: =SUM(Quarterly!#REF!) -> #REF! | G24: =SUM(Quarterly!#REF!) -> #REF! | H24: =SUM(Quarterly!#REF!) -> #REF! | I24: =SUM(Quarterly!#REF!) -> #REF! | J24: =Quarterly!#REF!*4 -> #REF! | K24: =IFERROR(E24/D24-1,0) -> 0 | L24: =IFERROR(F24/E24-1,0) -> 0 | M24: =IFERROR(G24/F24-1,0) -> 0 | N24: =IFERROR(H24/G24-1,0) -> 0 | O24: =IFERROR(I24/H24-1,0) -> 0 | P24: =IFERROR(J24/I24-1,0) -> 0
C25: Cloud Services | D25: =SUM(Quarterly!E24:I24) -> 50000 | E25: =SUM(Quarterly!J24:M24) -> 40000 | F25: =SUM(Quarterly!N24:Q24) -> 40000 | G25: =SUM(Quarterly!R24:U24) -> 40000 | H25: =SUM(Quarterly!V24:Y24) -> 40000 | I25: =SUM(Quarterly!Z24:AC24) -> 40000 | J25: =Quarterly!AD24*4 -> 40000 | K25: =IFERROR(E25/D25-1,0) -> -0.2 | L25: =IFERROR(F25/E25-1,0) -> 0 | M25: =IFERROR(G25/F25-1,0) -> 0 | N25: =IFERROR(H25/G25-1,0) -> 0 | O25: =IFERROR(I25/H25-1,0) -> 0 | P25: =IFERROR(J25/I25-1,0) -> 0
C26: US Market | D26: =SUM(Quarterly!E25:I25) -> 0 | E26: =SUM(Quarterly!J25:M25) -> 0 | F26: =SUM(Quarterly!N25:Q25) -> 0 | G26: =SUM(Quarterly!R25:U25) -> 10000 | H26: =SUM(Quarterly!V25:Y25) -> 40000 | I26: =SUM(Quarterly!Z25:AC25) -> 40000 | J26: =Quarterly!AD25*4 -> 40000 | K26: =IFERROR(E26/D26-1,0) -> 0 | L26: =IFERROR(F26/E26-1,0) -> 0 | M26: =IFERROR(G26/F26-1,0) -> 0 | N26: =IFERROR(H26/G26-1,0) -> 3 | O26: =IFERROR(I26/H26-1,0) -> 0 | P26: =IFERROR(J26/I26-1,0) -> 0
C27: New Customer Acquistion (B2C) | D27: =SUM(Quarterly!#REF!) -> #REF! | E27: =SUM(Quarterly!#REF!) -> #REF! | F27: =SUM(Quarterly!#REF!) -> #REF! | G27: =SUM(Quarterly!#REF!) -> #REF! | H27: =SUM(Quarterly!#REF!) -> #REF! | I27: =SUM(Quarterly!#REF!) -> #REF! | J27: =Quarterly!#REF!*4 -> #REF! | K27: =IFERROR(E27/D27-1,0) -> 0 | L27: =IFERROR(F27/E27-1,0) -> 0 | M27: =IFERROR(G27/F27-1,0) -> 0 | N27: =IFERROR(H27/G27-1,0) -> 0 | O27: =IFERROR(I27/H27-1,0) -> 0 | P27: =IFERROR(J27/I27-1,0) -> 0
C28: Cloud Services | D28: =SUM(Quarterly!E26:I26) -> 0 | E28: =SUM(Quarterly!J26:M26) -> 0 | F28: =SUM(Quarterly!N26:Q26) -> 0 | G28: =SUM(Quarterly!R26:U26) -> 10000 | H28: =SUM(Quarterly!V26:Y26) -> 40000 | I28: =SUM(Quarterly!Z26:AC26) -> 40000 | J28: =Quarterly!AD26*4 -> 40000 | K28: =IFERROR(E28/D28-1,0) -> 0 | L28: =IFERROR(F28/E28-1,0) -> 0 | M28: =IFERROR(G28/F28-1,0) -> 0 | N28: =IFERROR(H28/G28-1,0) -> 3 | O28: =IFERROR(I28/H28-1,0) -> 0 | P28: =IFERROR(J28/I28-1,0) -> 0
C29: Physical Office | D29: =SUM(Quarterly!E27:I27) -> 50000 | E29: =SUM(Quarterly!J27:M27) -> 40000 | F29: =SUM(Quarterly!N27:Q27) -> 40000 | G29: =SUM(Quarterly!R27:U27) -> 50000 | H29: =SUM(Quarterly!V27:Y27) -> 80000 | I29: =SUM(Quarterly!Z27:AC27) -> 80000 | J29: =Quarterly!AD27*4 -> 80000 | K29: =IFERROR(E29/D29-1,0) -> -0.2 | L29: =IFERROR(F29/E29-1,0) -> 0 | M29: =IFERROR(G29/F29-1,0) -> 0.25 | N29: =IFERROR(H29/G29-1,0) -> 0.6 | O29: =IFERROR(I29/H29-1,0) -> 0 | P29: =IFERROR(J29/I29-1,0) -> 0
C30: UK Market | D30: =SUM(Quarterly!E28:I28) -> 50000 | E30: =SUM(Quarterly!J28:M28) -> 40000 | F30: =SUM(Quarterly!N28:Q28) -> 40000 | G30: =SUM(Quarterly!R28:U28) -> 40000 | H30: =SUM(Quarterly!V28:Y28) -> 40000 | I30: =SUM(Quarterly!Z28:AC28) -> 40000 | J30: =Quarterly!AD28*4 -> 40000 | K30: =IFERROR(E30/D30-1,0) -> -0.2 | L30: =IFERROR(F30/E30-1,0) -> 0 | M30: =IFERROR(G30/F30-1,0) -> 0 | N30: =IFERROR(H30/G30-1,0) -> 0 | O30: =IFERROR(I30/H30-1,0) -> 0 | P30: =IFERROR(J30/I30-1,0) -> 0
C31: Rent | D31: =SUM(Quarterly!E29:I29) -> 50000 | E31: =SUM(Quarterly!J29:M29) -> 40000 | F31: =SUM(Quarterly!N29:Q29) -> 40000 | G31: =SUM(Quarterly!R29:U29) -> 40000 | H31: =SUM(Quarterly!V29:Y29) -> 40000 | I31: =SUM(Quarterly!Z29:AC29) -> 40000 | J31: =Quarterly!AD29*4 -> 40000 | K31: =IFERROR(E31/D31-1,0) -> -0.2 | L31: =IFERROR(F31/E31-1,0) -> 0 | M31: =IFERROR(G31/F31-1,0) -> 0 | N31: =IFERROR(H31/G31-1,0) -> 0 | O31: =IFERROR(I31/H31-1,0) -> 0 | P31: =IFERROR(J31/I31-1,0) -> 0
C32: Utilities and Maintenance | D32: =SUM(Quarterly!#REF!) -> #REF! | E32: =SUM(Quarterly!#REF!) -> #REF! | F32: =SUM(Quarterly!#REF!) -> #REF! | G32: =SUM(Quarterly!#REF!) -> #REF! | H32: =SUM(Quarterly!#REF!) -> #REF! | I32: =SUM(Quarterly!#REF!) -> #REF! | J32: =Quarterly!#REF!*4 -> #REF! | K32: =IFERROR(E32/D32-1,0) -> 0 | L32: =IFERROR(F32/E32-1,0) -> 0 | M32: =IFERROR(G32/F32-1,0) -> 0 | N32: =IFERROR(H32/G32-1,0) -> 0 | O32: =IFERROR(I32/H32-1,0) -> 0 | P32: =IFERROR(J32/I32-1,0) -> 0
C33: US Market | D33: =SUM(Quarterly!E30:I30) -> 0 | E33: =SUM(Quarterly!J30:M30) -> 0 | F33: =SUM(Quarterly!N30:Q30) -> 0 | G33: =SUM(Quarterly!R30:U30) -> 10000 | H33: =SUM(Quarterly!V30:Y30) -> 40000 | I33: =SUM(Quarterly!Z30:AC30) -> 40000 | J33: =Quarterly!AD30*4 -> 40000 | K33: =IFERROR(E33/D33-1,0) -> 0 | L33: =IFERROR(F33/E33-1,0) -> 0 | M33: =IFERROR(G33/F33-1,0) -> 0 | N33: =IFERROR(H33/G33-1,0) -> 3 | O33: =IFERROR(I33/H33-1,0) -> 0 | P33: =IFERROR(J33/I33-1,0) -> 0
C34: Rent | D34: =SUM(Quarterly!E31:I31) -> 0 | E34: =SUM(Quarterly!J31:M31) -> 0 | F34: =SUM(Quarterly!N31:Q31) -> 0 | G34: =SUM(Quarterly!R31:U31) -> 10000 | H34: =SUM(Quarterly!V31:Y31) -> 40000 | I34: =SUM(Quarterly!Z31:AC31) -> 40000 | J34: =Quarterly!AD31*4 -> 40000 | K34: =IFERROR(E34/D34-1,0) -> 0 | L34: =IFERROR(F34/E34-1,0) -> 0 | M34: =IFERROR(G34/F34-1,0) -> 0 | N34: =IFERROR(H34/G34-1,0) -> 3 | O34: =IFERROR(I34/H34-1,0) -> 0 | P34: =IFERROR(J34/I34-1,0) -> 0
C35: Utilities and Maintenance | D35: =SUM(Quarterly!#REF!) -> #REF! | E35: =SUM(Quarterly!#REF!) -> #REF! | F35: =SUM(Quarterly!#REF!) -> #REF! | G35: =SUM(Quarterly!#REF!) -> #REF! | H35: =SUM(Quarterly!#REF!) -> #REF! | I35: =SUM(Quarterly!#REF!) -> #REF! | J35: =Quarterly!#REF!*4 -> #REF! | K35: =IFERROR(E35/D35-1,0) -> 0 | L35: =IFERROR(F35/E35-1,0) -> 0 | M35: =IFERROR(G35/F35-1,0) -> 0 | N35: =IFERROR(H35/G35-1,0) -> 0 | O35: =IFERROR(I35/H35-1,0) -> 0 | P35: =IFERROR(J35/I35-1,0) -> 0

Sheet Assumptions
B2: Revenue Model & Pricing Assumptions
B4: Subscription Plans (SaaS Model) | C4: GBP / Mth
B5: Basic | C5: 0
B6: Pro | C6: 40
B7: Enterprise | C7: 200
B8: Userbase QoQ Growth Rate | C8: 0.45
B9: Data Licensing | C9: GBP / Year
B10: Small Firms | C10: 10000
B11: Large Institutions | C11: 50000
B13: API Monetization
B14: Per API Call | C14: 0.01
B16: Transaction Fees (Future Expansion)
B17: Commission Based | C17: 0.02
B19: Fixed & Variable Cost Assumptions
B21: Fixed Costs | C21: GBP / Mth
B22: Office Rent | C22: 5000
B23: Salaries (Initial Team) | C23: 30000
B24: Cloud & Server Costs | C24: 3000
B25: Legal & Compliance | C25: 2000
B27: Variable Costs
B28: Customer Acquisition (Ads, SEO, PR) | C28: 0.2 | D28: % of Revenue
B29: Data Acquisition & Licensing | C29: 1000 | D29: Per Dataset
B30: Support & Maintenance | C30: 0.1 | D30: % of Revenue
B33: Investment & Funding Assumptions
B35: Seed Round Target | C35: 500000
B37: Use of Funds
B38: Product Development (AI, GIS, UX Improvements) | C38: 0.5
B39: Marketing & Sales | C39: 0.3
B40: Team Expansion (Hiring Engineers, analysts, & sales staff) | C40: 0.15
B41: Legal & Compliance | C41: 0.05

Sheet DCF
B2: Quarterly Cashflow | D2: FY26 | F2: FY27 | J2: FY28 | N2: FY29 | R2: FY30 | V2: FY31 | Z2: FY32 | AD2: FY33
D3: Q4 | E3: Q1 | F3: Q2 | G3: Q3 | H3: Q4 | I3: Q1 | J3: Q2 | K3: Q3 | L3: Q4 | M3: Q1 | N3: Q2 | O3: Q3 | P3: Q4 | Q3: Q1 | R3: Q2 | S3: Q3 | T3: Q4 | U3: Q1 | V3: Q2 | W3: Q3 | X3: Q4 | Y3: Q1 | Z3: Q2 | AA3: Q3 | AB3: Q4 | AC3: Q1 | AD3: Q2 | AE3: Q3 | AF3: Q4 | AG3: Q1
C4: SUM | D4: 45931 | E4: =EDATE(D4,3) -> 46023 | F4: =EDATE(E4,3) -> 46113 | G4: =EDATE(F4,3) -> 46204 | H4: =EDATE(G4,3) -> 46296 | I4: =EDATE(H4,3) -> 46388 | J4: =EDATE(I4,3) -> 46478 | K4: =EDATE(J4,3) -> 46569 | L4: =EDATE(K4,3) -> 46661 | ... AG4: =EDATE(AF4,3) -> 48580
B5: GANTT Chart | D5: Prototype
D6: Fundraising
F7: Product Development | H7: Market Presence
H8: Marketing, Sales, Product Improvement, Expansion
Z9: Exit
I10: =I11/H12 -> 0.45 | J10: =J11/I12 -> 0.45 | K10: =K11/J12 -> 0.10463734 | L10: =L11/K12 -> 0.45 | M10: =M11/L12 -> 0.45 | N10: =N11/M12 -> 0.45 | O10: =O11/N12 -> 0.45 | P10: =P11/O12 -> 0.45 | ... Y10: =Y11/X12 -> 0.45
B11: Sales & Marketing Plan - No. of Users | I11: =I12-H12 -> 22.5 | J11: =J12-I12 -> 32.625 | K11: 11 | L11: =L12-K12 -> 68.594063 | M11: =M12-L12 -> 99.461391 | N11: =N12-M12 -> 144.21902 | O11: =O12-N12 -> 209.11757 | P11: =P12-O12 -> 303.22048 | Q11: =Q12-P12 -> 439.6697 | R11: =R12-Q12 -> 637.52106 | S11: =S12-R12 -> 924.40554 | ... Y11: =Y12-X12 -> 8591.5308
B12: Subscription Plans (SaaS Model) | C12: =SUM(D12:Y12) -> 89092.314 | H12: 50 | I12: =H12*(1+Assumptions!$C$8) -> 72.5 | J12: =I12*(1+Assumptions!$C$8) -> 105.125 | K12: =J12*(1+Assumptions!$C$8) -> 152.43125 | L12: =K12*(1+Assumptions!$C$8) -> 221.02531 | M12: =L12*(1+Assumptions!$C$8) -> 320.4867 | N12: =M12*(1+Assumptions!$C$8) -> 464.70572 | O12: =N12*(1+Assumptions!$C$8) -> 673.82329 | P12: =O12*(1+Assumptions!$C$8) -> 977.04378 | ... Y12: =X12*(1+Assumptions!$C$8) -> 27683.822
B13: Freemium | C13: =SUM(D13:Y13) -> 122.5 | H13: =H12*100% -> 50 | I13: =I12*100% -> 72.5
B14: Basic | C14: =SUM(D14:Y14) -> 59641.738 | J14: =J$12*71% -> 74.63875 | K14: =K$12*71% -> 108.22619 | L14: =L$12*71% -> 156.92797 | M14: =M$12*71% -> 227.54556 | N14: =N$12*67% -> 311.35283 | O14: =O$12*67% -> 451.46161 | P14: =P$12*67% -> 654.61933 | Q14: =Q$12*67% -> 949.19803 | R14: =R$12*67% -> 1376.3371 | S14: =S$12*67% -> 1995.6889 | T14: =T$12*67% -> 2893.7488 | U14: =U$12*67% -> 4195.9358 | ... Y14: =Y$12*67% -> 18548.16
B15: Pro | C15: =SUM(D15:Y15) -> 24037.831 | J15: =J$12*29% -> 30.48625 | K15: =K$12*29% -> 44.205062 | L15: =L$12*29% -> 64.097341 | M15: =M$12*29% -> 92.941144 | N15: =N$12*27% -> 125.47054 | O15: =O$12*27% -> 181.93229 | P15: =P$12*27% -> 263.80182 | Q15: =Q$12*27% -> 382.51264 | R15: =R$12*27% -> 554.64333 | S15: =S$12*27% -> 804.23282 | T15: =T$12*27% -> 1166.1376 | U15: =U$12*27% -> 1690.8995 | ... Y15: =Y$12*27% -> 7474.6318
B16: Enterprise | C16: =SUM(D16:Y16) -> 5290.2448 | N16: =N$12*(1-67%-27%) -> 27.882343 | O16: =O$12*(1-67%-27%) -> 40.429398 | P16: =P$12*(1-67%-27%) -> 58.622627 | Q16: =Q$12*(1-67%-27%) -> 85.002808 | R16: =R$12*(1-67%-27%) -> 123.25407 | S16: =S$12*(1-67%-27%) -> 178.7184 | T16: =T$12*(1-67%-27%) -> 259.14169 | U16: =U$12*(1-67%-27%) -> 375.75545 | ... Y16: =Y$12*(1-67%-27%) -> 1661.0293
B18: Data Licensing
B19: Small Firms
B20: Large Institutions
B22: Revenue Stream
B23: Subscription Plans (SaaS Model)
B24: Basic | C24: =SUM(D24:Y24) -> 0 | J24: =Assumptions!$C$5*3*J14 -> 0 | K24: =Assumptions!$C$5*3*K14 -> 0 | L24: =Assumptions!$C$5*3*L14 -> 0 | M24: =Assumptions!$C$5*3*M14 -> 0 | N24: =Assumptions!$C$5*3*N14 -> 0 | O24: =Assumptions!$C$5*3*O14 -> 0 | P24: =Assumptions!$C$5*3*P14 -> 0 | Q24: =Assumptions!$C$5*3*Q14 -> 0 | ... Y24: =Assumptions!$C$5*3*Y14 -> 0
B25: Pro | C25: =SUM(D25:Y25) -> 2884539.7 | J25: =Assumptions!$C$6*3*DCF!J15 -> 3658.35 | K25: =Assumptions!$C$6*3*DCF!K15 -> 5304.6075 | L25: =Assumptions!$C$6*3*DCF!L15 -> 7691.6809 | M25: =Assumptions!$C$6*3*DCF!M15 -> 11152.937 | N25: =Assumptions!$C$6*3*DCF!N15 -> 15056.465 | O25: =Assumptions!$C$6*3*DCF!O15 -> 21831.875 | P25: =Assumptions!$C$6*3*DCF!P15 -> 31656.218 | Q25: =Assumptions!$C$6*3*DCF!Q15 -> 45901.517 | ... Y25: =Assumptions!$C$6*3*DCF!Y15 -> 896955.82
B26: Enterprise | C26: =SUM(D26:Y26) -> 3174146.9 | N26: =Assumptions!$C$7*3*N16 -> 16729.406 | O26: =Assumptions!$C$7*3*O16 -> 24257.639 | P26: =Assumptions!$C$7*3*P16 -> 35173.576 | Q26: =Assumptions!$C$7*3*Q16 -> 51001.685 | R26: =Assumptions!$C$7*3*R16 -> 73952.443 | S26: =Assumptions!$C$7*3*S16 -> 107231.04 | T26: =Assumptions!$C$7*3*T16 -> 155485.01 | U26: =Assumptions!$C$7*3*U16 -> 225453.27 | ... Y26: =Assumptions!$C$7*3*Y16 -> 996617.58
B27: Total from Subscription | C27: =SUM(C24:C26) -> 6058686.6 | D27: =SUM(D24:D26) -> 0 | E27: =SUM(E24:E26) -> 0 | F27: =SUM(F24:F26) -> 0 | G27: =SUM(G24:G26) -> 0 | H27: =SUM(H24:H26) -> 0 | I27: =SUM(I24:I26) -> 0 | J27: =SUM(J24:J26) -> 3658.35 | ... Y27: =SUM(Y24:Y26) -> 1893573.4
B29: Data Licensing
B30: Small Firms | L30: =Assumptions!C10 -> 10000 | P30: =L30 -> 10000 | T30: =P30 -> 10000 | X30: =T30 -> 10000
B31: Large Institutions | M31: =Assumptions!C11 -> 50000 | R31: =M31 -> 50000 | W31: =R31 -> 50000
B33: API Monetization
B34: Per API Call
B36: Transaction Fees (Future Expansion)
B37: Commission Based
B39: Total Revenue | D39: =D37+D34+D31+D30+D27 -> 0 | E39: =E37+E34+E31+E30+E27 -> 0 | F39: =F37+F34+F31+F30+F27 -> 0 | G39: =G37+G34+G31+G30+G27 -> 0 | H39: =H37+H34+H31+H30+H27 -> 0 | I39: =I37+I34+I31+I30+I27 -> 0 | J39: =J37+J34+J31+J30+J27 -> 3658.35 | K39: =K37+K34+K31+K30+K27 -> 5304.6075 | ... Y39: =Y37+Y34+Y31+Y30+Y27 -> 1893573.4
B41: Costing | Y41: =Y39*4/10^6 -> 7.5742936
B42: =Quarterly!C5 -> Staff (in £ '000) | C42: {=SUM(D42:Y42/$C$56)} -> 0.46428298 | D42: =D43+D44 -> 20000 | E42: =E43+E44 -> 27500 | F42: =F43+F44 -> 46500 | G42: =G43+G44 -> 46500 | H42: =H43+H44 -> 50000 | I42: =I43+I44 -> 50000 | J42: =J43+J44 -> 50000 | K42: =K43+K44 -> 50000 | ... Y42: =Y43+Y44 -> 228000
B43: =Quarterly!C6 -> UK Market | C43: {=SUM(D43:Y43/$C$56)} -> 0.32551542 | D43: =Quarterly!E6 -> 20000 | E43: =Quarterly!F6 -> 27500 | F43: =Quarterly!G6 -> 46500 | G43: =Quarterly!H6 -> 46500 | H43: =Quarterly!I6 -> 50000 | I43: =Quarterly!J6 -> 50000 | J43: =Quarterly!K6 -> 50000 | K43: =Quarterly!L6 -> 50000 | ... Y43: =Quarterly!Z6 -> 114000
B44: =Quarterly!C14 -> US Market | C44: {=SUM(D44:Y44/$C$56)} -> 0.13876756 | D44: =Quarterly!E14 -> 0 | E44: =Quarterly!F14 -> 0 | F44: =Quarterly!G14 -> 0 | G44: =Quarterly!H14 -> 0 | H44: =Quarterly!I14 -> 0 | I44: =Quarterly!J14 -> 0 | J44: =Quarterly!K14 -> 0 | K44: =Quarterly!L14 -> 0 | ... Y44: =Quarterly!Z14 -> 114000
B45: =Quarterly!C22 -> Technology Cost (in £ '000) | C45: {=SUM(D45:Y45/$C$56)} -> 0.056805433 | D45: =D46+D47 -> 10000 | E45: =E46+E47 -> 10000 | F45: =F46+F47 -> 10000 | G45: =G46+G47 -> 10000 | H45: =H46+H47 -> 10000 | I45: =I46+I47 -> 10000 | J45: =J46+J47 -> 10000 | K45: =K46+K47 -> 10000 | ... Y45: =Y46+Y47 -> 20000
B46: =Quarterly!C23 -> UK Market | C46: {=SUM(D46:Y46/$C$56)} -> 0.04463284 | D46: =Quarterly!E24 -> 10000 | E46: =Quarterly!F24 -> 10000 | F46: =Quarterly!G24 -> 10000 | G46: =Quarterly!H24 -> 10000 | H46: =Quarterly!I24 -> 10000 | I46: =Quarterly!J24 -> 10000 | J46: =Quarterly!K24 -> 10000 | K46: =Quarterly!L24 -> 10000 | ... Y46: =Quarterly!Z24 -> 10000
B47: =Quarterly!C25 -> US Market | C47: {=SUM(D47:Y47/$C$56)} -> 0.012172593 | D47: =Quarterly!E26 -> 0 | E47: =Quarterly!F26 -> 0 | F47: =Quarterly!G26 -> 0 | G47: =Quarterly!H26 -> 0 | H47: =Quarterly!I26 -> 0 | I47: =Quarterly!J26 -> 0 | J47: =Quarterly!K26 -> 0 | K47: =Quarterly!L26 -> 0 | ... Y47: =Quarterly!Z26 -> 10000
B48: =Quarterly!C27 -> Physical Office | C48: {=SUM(D48:Y48/$C$56)} -> 0.056805433 | D48: =SUM(D49:D50) -> 10000 | E48: =SUM(E49:E50) -> 10000 | F48: =SUM(F49:F50) -> 10000 | G48: =SUM(G49:G50) -> 10000 | H48: =SUM(H49:H50) -> 10000 | I48: =SUM(I49:I50) -> 10000 | J48: =SUM(J49:J50) -> 10000 | K48: =SUM(K49:K50) -> 10000 | ... Y48: =SUM(Y49:Y50) -> 20000
...
